에러 핸들링은 프로그램의 에러를 처리하는 방법을 말한다. 프로그램에서 에러는 언제 어디서나 발생할 수 있다. 대부분 에러는 프로그래머 실수로 발생하지만 때로는 메모리가 부족하거나 디스크 공간 부족 또는 네트워크 단절이 원인이 되어 발생하기 한다. 에러가 발생하면 경우에 따라 빠르게 프로그램을 종료하거나 적절한 방식으로 처리하여 프로그램을 계속 실행시킬 수 있다.

# 에러 반환
에러를 처리하는 가장 기본적인 방식은 에러를 반환하고 알맞게 처리하는 방식이다. 예를 들어 `ReadFile()` 함수로 파일을 읽을 때 해당하는 파일이 없어서 에러가 발생했다고 하자. 이럴 때 프로그램이 강제 종료되는 것 보다는 적절한 메시지를 출려갛고 다른 파일을 읽거나 임시 파일을 생성한다면 훨씬 사용자 경험이 좋을 것이다. 

```go
package main

import (
	"bufio"
	"fmt"
	"os"
)

func ReadFile(filename string) (string, error) {
	file, err := os.Open(filename)
	if err != nil {
		return "", err
	}
	defer file.Close()
	rd := bufio.NewReader(file)
	line, _ := rd.ReadString('\n')
	return line, nil
}

func WriteFile(filename string, line string) error {
	file, err := os.Create(filename)
	if err != nil {
		return err
	}
	defer file.Close()
	_, err = fmt.Fprintln(file, line)
	return err
}

const filename string = "data.txt"

func main() {
	line, err := ReadFile(filename)
	if err != nil {
		err = WriteFile(filename, "This is WriteFile")
		if err != nil {
			fmt.Println("파일 생성에 실패했습니다.", err)
			return
		}
		line, err = ReadFile(filename)
		if err != nil {
			fmt.Println("파일 읽기에 실패했습니다.", err)
			return
		}
	}
	fmt.Println("파일 내용:", line)
}
```

## 사용자 에러 반환
직접 에러를 만들어서 반환하는 방법 보기
```go
package main

import (
	"fmt"
	"math"
)

func Sqrt(f float64) (float64, error) {
	if f < 0 {
		return 0, fmt.Errorf(
			"제곱근은 양수여야 합니다. g: %g", f)
	}
	return math.Sqrt(f), nil
}

func main() {
	sqrt, err := Sqrt(-3)
	if err != nil {
		fmt.Printf("Error: %v\n", err)
		return
	}
	fmt.Printf("Sqrt(-2) = %v\n", sqrt)
}
```

```
Error: 제곱근은 양수여야 합니다. f: -3
```

# 에러 타입
`error` 타입은 인터페이스로 문자열을 반환하는 `Error()` 메서드로 구성되어 있다.
```go
type error interface {
	Error() string
}
```

즉 어떤 타입이든 문자열을 반환하는 `Error()` 메서드를 포함하고 있다면 에러로 사용할 수 있다.

회원 가입 시 암호 길이를 검사하는 예제

```go
package main

import "fmt"

type PasswordError struct {
	Len        int
	RequireLen int
}

func (err PasswordError) Error() string {
	return "암호가 짧습니다."
}

func RegisterAccount(id, password string) error {
	if len(password) < 8 {
		return PasswordError{len(password), 8}
	}
	return nil
}

func main() {
	err := RegisterAccount("myID", "myPw")
	if err != nil {
		if errInfo, ok := err.(PasswordError); ok {
			fmt.Printf("%v, %d, %d", errInfo, errInfo.Len, errInfo.RequireLen)
		}
	}
}
```

```
암호가 짧습니다. Len: 4, RequireLen: 8
```

## 에러 랩핑
때론 에러를 감싸서 새로운 에러를 만들어야할 수도 있다. 예를 들어 파일에서 텍스트를 읽어서 특정 타입의 데이터로 변환하는 경우 파일 읽기에서 발생하는 에러도 필요하지만 텍스트의 몇 번째 줄의 몇 번째 칸에서 에러가 발생했는지도 알면 더 유용하다. 이럴 때 파일 읽기에서 발생한 에러를 감싸고 그 바깥에 줄과 칸 정보를 넣으면 된다.

```go
package main

import (
	"bufio"
	"errors"
	"fmt"
	"strconv"
	"strings"
)

func MulipleFromString(str string) (int, error) {
	scanner := bufio.NewScanner(strings.NewReader(str))
	scanner.Split(bufio.ScanWords)

	pos := 0
	a, n, err := readNextInt(scanner)
	if err != nil {
		return 0, fmt.Errorf("failed to readNextInt(), pos: %d, err:%w", pos, err)
	}

	pos += n + 1
	b, n, err := readNextInt(scanner)
	if err != nil {
		return 0, fmt.Errorf("failed to readNextInt(), pos: %d, err:%w", pos, err)
	}
	return a * b, nil
}

func readNextInt(scanner *bufio.Scanner) (int, int, error) {
	if !scanner.Scan() {
		return 0, 0, fmt.Errorf("failed to scan")
	}
	word := scanner.Text()
	number, err := strconv.Atoi(word)
	if err != nil {
		return 0, 0, fmt.Errorf("failed to conver word to int, word:%s, err:%w",
			word, err)
	}
	return number, len(word), nil
}

func readEq(eq string) {
	rst, err := MulipleFromString(eq)
	if err == nil {
		fmt.Println(rst)
	} else {
		fmt.Println(err)
		var numError *strconv.NumError
		if errors.As(err, &numError) {
			fmt.Println("NumberError: ", numError)
		}
	}
}

func main() {
	readEq("123 3")
	readEq("123 abc")
}
```

에러가 발생한 경우 `fmt.Errorf()` 함수의 `%w` 서식문자로 에러를 감쌌다.
```
fmt.Errorf("Error: %w", err)
```
감싸진 에러를 다시 가져올 때는 `errors` 패키지의 `As()` 함수를 사용하면 된다. `errors.As()` 는 체이닝된 `err` 중 두 번째 인수로 받은 에러 타입으로 변환될 수 있는 에러가 있다면 변환하여 값을 넣고 true를 반환하는 함수이다. 따라서 감싸진 에러를 검사하고 각 에러 타입별로 다른 처리를 할 수가 있다. 

# 패닉
패닉은 프로그램을 정상 진행시키기 어려운 상황을 만났을 때 프로그램 흐름을 중지시키는 기능이다. Go 언어는 내장 함수 `panic()`으로 패닉 기능을 제공한다. 지금까지 error 인터페이스를 사용해 에러를 처리했다. error 인터페이스를 사용하면 호출자에게 에러가 발생한 이유를 알려줄 수 있었다. 그런데 프로그램을 수행하다 보면 예기치 못한 에러에 직면하기도 한다. 예를 들어 버그가 발생해 잘못된 메모리에 접근하거나 메모리가 부족하면 프로그램이 더는 실행 불가능할 수 있다. panic() 함수를 사용하면 문제 발생 시점에 프로그램을 바로 종료시켜서 빠르게 문제 발생 시점을 알 수 있다. 버그 수정에 유용한 방식이다. 
panic() 내장 함수를 호출하고 인수로 에러 메시지를 입력하면 프로그램을 즉시 종료하고 에러 메시지를 출력하고 함수 호출 순서를 나타내는 콜 스택을 표시한다. 이 정보를 사용해 에러가 발생한 경로를 파악할 수 있다.

```go
package main

import "fmt"

func divide(a, b int) {
	if b == 0 {
		panic("b는 0일 수 없습니다.")
	}
	fmt.Printf("%d / %d = %d\n", a, b, a/b)
}

func main() {
	divide(9, 3)
	divide(9, 4)
	divide(9, 0)
}
```

```
9 / 3 = 3
9 / 4 = 2
panic: b는 0일 수 없습니다.

goroutine 1 [running]:
main.divide(0x9, 0x0)
        /home/user/goproject/ch23/ex.go:7 +0x175
main.main()
        /home/user/goproject/ch23/ex.go:15 +0x5f
```

콜 스택이란 panic이 발생한 마지막 함수 위치부터 역순으로 호출 순서를 표시한다. 

## 패닉 생성
패닉은 내장 함수 panic()을 사용해서 발생시킬 수 있다. 
```go
func panic(interface{})
```

위와 같이 panic() 내장 함수의 인수로 interface{} 타입 즉 모든 타입을 사용할 수 있다. 일반적으로 string 타입 메시지나 fmt.Errorf() 함수를 이용해서 만들어진 에러 타입을 주로 사용한다.

## 패닉 전파 그리고 복구
프로그램을 개발할 때는 빠르게 문제점을 파악하고 수정하는게 중요하다. 하지만 사용자에게 프로그램이 전달되고 난 뒤에는 문제가 발생하더라도 프로그램이 종료되는 대신 에러메시지를 표시하고 복구를 시도하는게 더 나은 선택일 수 있다. 
panic은 호출 순서를 거슬러 올라가며 전파된다. 만약 함수 호출 과정이 main() -> f() -> g() -> h() 였고 h() 함수에서 패닉이 발생하면 호출 순서를 거꾸로 올라가면서 g() -> f() -> main() 함수로 전달된다. main() 함수에서까지 복구되지 않으면 프로그램이 그제서야 강제종료된다. 어느 단계에서든 패닉은 복구된 시점부터 프로그램이 계속된다. recover() 함수를 호출해 패닉 복구를 할 수 있다. recover() 함수가 호출되는 시점에 패닉이 전파 중이면 panic 객체를 반환하고 그렇지 않으면 nil을 반환한다. 

```go
package main

import "fmt"

func f() {
	fmt.Println("f() 함수 시작")
	defer func() {
		if r := recover(); r != nil {
			fmt.Println("panic 복구 -", r)
		}
	}()

	g()
	fmt.Println("f() 함수 끝")
}

func g() {
	fmt.Printf("9 / 3 = %d\n", h(9, 3))
	fmt.Printf("9 / 3 = %d\n", h(9, 0))
}

func h(a, b int) int {
	if b == 0 {
		panic("0으로 나눌 수 없습니다.")
	}
	return a / b
}

func main() {
	f()
	fmt.Println("프로그램이 계속 실행됨")
}
```

```
f() 함수 시작
9 / 3 = 3
panic 복구 - 0으로 나눌 수 없습니다.
프로그램이 계속 실행됨
```

패닉이 f() 까지 전파되지만 함수 종료 직전 defer가 된 함수안에 recover() 함수가 실행되어 panic이 있으면 복구하고 패닉 값을 찾는다. 패닉이 없으면 nil을 반환한다. 복구 후에는 계속 프로그램이 실행된다. 따라서 패닉으로 인해 f() 함수가 종료되기 때문에 `f() 함수 끝`은  출력되지 않는 것이다. 대신 프로그램은 계속 실행되어 `프로그램이 계속 실행됨` 은 출력된다.

recover()는 제한적으로 사용하는 것이 좋다. 패닉이 발생되면 그 즉시 호출 순서를 역순으로 전파하기 때문에 복구가 되더라도 프로그램이 불안정할 수 있다. 예를 들어 파일에 데이터를 쓰는 프로그램에서 데이터를 일부만 쓴 상태에서 패닉이 발생하고 다시 복구하면 데이터가 비정상적으로 저장된 상태로 남게된다. 이럴 때는 그냥 복구하지 않거나 데이터가 비정상적으로 남아있지 않도록 확실히 지워줘야 한다.

## `recover()` 결과
내장 함수 `recover()` 는 발생한 panic 객체를 반환해준다.
```go
fucn recover() interface{}
```
panic() 함수가 인수로 interface{} 를 받았기 때문에 recover() 는 interface{} 를 반환해야한다. 그래서 recover()로 반환한 타입을 실제 사용하려면 다음과 같이 타입 검사를 해야한다.
```go
if r, ok := recover().(net.Error); ok {
	fmt.Println("r is net.Error type")
}
```
발생한 패닉이 특정 타입인지 확인해서 해당 타입 패닉에 대한 처리를 추가하고 싶은 경우 위와같은 구문을 사용해서 타입 검사를 해야한다.